<?xml version="1.0" ?>

<robot name="pendulum">

	<link name="base_link">
		<inertial>
			<origin xyz="0.0 0.0 0.0" rpy="0 0 0" />
			<mass value="1" />
			<inertia ixx="0.1" iyy="0.1" izz="0.1" ixy="0" ixz="0" iyz="0" />
		</inertial>
		<visual>
			<origin xyz="0.0 0.0 0.0" rpy="0 0 0" />
			<geometry>
				<sphere radius="0.1" />
			</geometry>
		</visual>
	</link>
	<link name="link1">
		<inertial>
			<origin xyz="0.0 0.0 -1.0" rpy="0 0 0" />
			<mass value="1.0" />
			<inertia ixx="0.1" iyy="0.1" izz="0.1" ixy="0" ixz="0" iyz="0" />
		</inertial>
		<visual>
			<origin xyz="0.0 0.0 -1.0" rpy="0 0 0" />
			<geometry>
				<sphere radius="0.1" />
			</geometry>
		</visual>
	</link>

	<joint name="j0" type="revolute">
		<parent link="base_link" />
		<child link="link1" />
		<origin xyz="0 0 0"/>
		<axis xyz="1 0 0" />
		<limit lower="-2.967" upper="2.967" effort="176" velocity="1.7104" />
	</joint>


</robot>
